<?xml version='1.0'?>
<sdf version='1.6'>
  <model name='tarot_iris_2'>
    <link name='frame'>
      <pose frame=''>0 0 0 0 -0 0</pose>
      <inertial>
        <pose frame=''>0.000981 0.012703 0.027324 0 -0 0</pose>
        <mass>9.83221</mass>
        <inertia>
          <ixx>0.0878747</ixx>
          <ixy>-0.00177596</ixy>
          <ixz>-0.000715106</ixz>
          <iyy>0.0760513</iyy>
          <iyz>-0.00798736</iyz>
          <izz>0.157183</izz>
        </inertia>
      </inertial>
      <collision name='frame_collision'>
        <pose frame=''>0 0 0 0 -0 0</pose>
        <geometry>
          <mesh>
            <scale>1 1 1</scale>
            <uri>model://tarot_2/meshes/frame.STL</uri>
          </mesh>
        </geometry>
      </collision>
      <collision name='frame_fixed_joint_lump__iris_base_collision_1'>
        <pose frame=''>-0.136788 0.234281 0.121134 3.14159 -0 -0.001828</pose>
        <geometry>
          <mesh>
            <scale>1 1 1</scale>
            <uri>model://tarot_2/meshes/iris_base.STL</uri>
          </mesh>
        </geometry>
      </collision>
      <collision name='frame_fixed_joint_lump__servo1_collision_2'>
        <pose frame=''>-0.147752 0.199501 0.100884 -3.14159 -1.57079 1.56897</pose>
        <geometry>
          <mesh>
            <scale>1 1 1</scale>
            <uri>model://tarot_2/meshes/servo1.STL</uri>
          </mesh>
        </geometry>
      </collision>
      <collision name='frame_fixed_joint_lump__servo2_collision_3'>
        <pose frame=''>0.147648 0.198961 0.100884 -3.14159 -1.57079 1.56897</pose>
        <geometry>
          <mesh>
            <scale>1 1 1</scale>
            <uri>model://tarot_2/meshes/servo2.STL</uri>
          </mesh>
        </geometry>
      </collision>
      <visual name='frame_visual'>
        <pose frame=''>0 0 0 0 -0 0</pose>
        <geometry>
          <mesh>
            <scale>1 1 1</scale>
            <uri>model://tarot_2/meshes/frame.STL</uri>
          </mesh>
        </geometry>
      </visual>
      <visual name='frame_fixed_joint_lump__iris_base_visual_1'>
        <pose frame=''>-0.136788 0.234281 0.121134 3.14159 -0 -0.001828</pose>
        <geometry>
          <mesh>
            <scale>1 1 1</scale>
            <uri>model://tarot_2/meshes/iris_base.STL</uri>
          </mesh>
        </geometry>
      </visual>
      <visual name='frame_fixed_joint_lump__servo1_visual_2'>
        <pose frame=''>-0.147752 0.199501 0.100884 -3.14159 -1.57079 1.56897</pose>
        <geometry>
          <mesh>
            <scale>1 1 1</scale>
            <uri>model://tarot_2/meshes/servo1.STL</uri>
          </mesh>
        </geometry>
      </visual>
      <visual name='frame_fixed_joint_lump__servo2_visual_3'>
        <pose frame=''>0.147648 0.198961 0.100884 -3.14159 -1.57079 1.56897</pose>
        <geometry>
          <mesh>
            <scale>1 1 1</scale>
            <uri>model://tarot_2/meshes/servo2.STL</uri>
          </mesh>
        </geometry>
      </visual>
    </link>
    <link name='iris_arm'>
      <pose frame=''>0.147648 0.198961 0.110884 3.09579 -0.066792 0.001232</pose>
      <inertial>
        <pose frame=''>0.145175 0.076715 0.009721 0 -0 0</pose>
        <mass>0.332476</mass>
        <inertia>
          <ixx>0.00124494</ixx>
          <ixy>-1.28654e-18</ixy>
          <ixz>-6.20297e-06</ixz>
          <iyy>0.00253784</iyy>
          <iyz>-2.24294e-18</iyz>
          <izz>0.00133715</izz>
        </inertia>
      </inertial>
      <collision name='iris_arm_collision'>
        <pose frame=''>0 0 0 0 -0 0</pose>
        <geometry>
          <mesh>
            <scale>1 1 1</scale>
            <uri>model://tarot_2/meshes/iris_arm.STL</uri>
          </mesh>
        </geometry>
      </collision>
      <visual name='iris_arm_visual'>
        <pose frame=''>0 0 0 0 -0 0</pose>
        <geometry>
          <mesh>
            <scale>1 1 1</scale>
            <uri>model://tarot_2/meshes/iris_arm.STL</uri>
          </mesh>
        </geometry>
      </visual>
    </link>
    <joint name='iris_swing' type='revolute'>
      <child>iris_arm</child>
      <parent>frame</parent>
      <axis>
        <xyz>0.997766 0 0.066812</xyz>
        <limit>
          <lower>-1e+16</lower>
          <upper>1e+16</upper>
        </limit>
        <dynamics>
          <spring_reference>0</spring_reference>
          <spring_stiffness>0</spring_stiffness>
        </dynamics>
        <use_parent_model_frame>0</use_parent_model_frame>
      </axis>
    </joint>
  </model>
</sdf>
